<?xml version="1.0"?>
<robot name="qbot">
    <link name="base_footprint"/>
    <joint name="base_footprint_joint" type="fixed"><parent link="base_footprint"/><child link="base_link"/><origin xyz="0 0 0" rpy="0 0 0"/></joint>

    <link name="base_link">
        <visual><origin xyz="0 0 0.06"/><geometry><cylinder length="0.10938" radius="0.178"/></geometry><material name="blue"><color rgba="0.0 0.0 0.8 1.0"/></material></visual>
        <collision><origin xyz="0 0 0.06"/><geometry><cylinder length="0.10938" radius="0.178"/></geometry></collision>
        <inertial><origin xyz="0 0 0.06"/><mass value="2.0"/><inertia ixx="0.0178" ixy="0.0" ixz="0.0" iyy="0.0178" iyz="0.0" izz="0.0316"/></inertial>
    </link>

    <link name="wheel_left_link">
        <visual><geometry><cylinder length="0.03" radius="0.05"/></geometry><material name="black"><color rgba="0.1 0.1 0.1 1.0"/></material></visual>
        <collision><geometry><cylinder length="0.03" radius="0.05"/></geometry></collision>
        <inertial><mass value="0.2"/><inertia ixx="0.00014" ixy="0.0" ixz="0.0" iyy="0.00014" iyz="0.0" izz="0.00025"/></inertial>
    </link>
    <joint name="wheel_left_joint" type="continuous"><parent link="base_link"/><child link="wheel_left_link"/><origin xyz="0 0.193 0.025" rpy="-1.5708 0 0"/><axis xyz="0 0 1"/></joint>

    <link name="wheel_right_link">
        <visual><geometry><cylinder length="0.03" radius="0.05"/></geometry><material name="black"><color rgba="0.1 0.1 0.1 1.0"/></material></visual>
        <collision><geometry><cylinder length="0.03" radius="0.05"/></geometry></collision>
        <inertial><mass value="0.2"/><inertia ixx="0.00014" ixy="0.0" ixz="0.0" iyy="0.00014" iyz="0.0" izz="0.00025"/></inertial>
    </link>
    <joint name="wheel_right_joint" type="continuous"><parent link="base_link"/><child link="wheel_right_link"/><origin xyz="0 -0.193 0.025" rpy="-1.5708 0 0"/><axis xyz="0 0 1"/></joint>

    <link name="caster_front_link">
        <visual><geometry><sphere radius="0.025"/></geometry><material name="black"><color rgba="0.1 0.1 0.1 1.0"/></material></visual>
        <collision><geometry><sphere radius="0.025"/></geometry></collision>
        <inertial><mass value="0.1"/><inertia ixx="0.0001" ixy="0" ixz="0" iyy="0.0001" iyz="0" izz="0.0001"/></inertial>
    </link>
    <joint name="caster_front_joint" type="fixed"><parent link="base_link"/><child link="caster_front_link"/><origin xyz="0.14 0 0" rpy="0 0 0"/></joint>

    <link name="caster_back_link">
        <visual><geometry><sphere radius="0.025"/></geometry><material name="black"><color rgba="0.1 0.1 0.1 1.0"/></material></visual>
        <collision><geometry><sphere radius="0.025"/></geometry></collision>
        <inertial><mass value="0.1"/><inertia ixx="0.0001" ixy="0" ixz="0" iyy="0.0001" iyz="0" izz="0.0001"/></inertial>
    </link>
    <joint name="caster_back_joint" type="fixed"><parent link="base_link"/><child link="caster_back_link"/><origin xyz="-0.14 0 0" rpy="0 0 0"/></joint>

    <gazebo reference="wheel_left_link"><mu1>1.0</mu1><mu2>1.0</mu2></gazebo>
    <gazebo reference="wheel_right_link"><mu1>1.0</mu1><mu2>1.0</mu2></gazebo>
    <gazebo reference="caster_front_link"><mu1>0.0</mu1><mu2>0.0</mu2></gazebo>
    <gazebo reference="caster_back_link"><mu1>0.0</mu1><mu2>0.0</mu2></gazebo>

    <link name="sensor_mount_link">
        <visual><geometry><box size="0.08 0.12 0.05"/></geometry><material name="red"><color rgba="0.8 0.0 0.0 1.0"/></material></visual>
        <collision><geometry><box size="0.08 0.12 0.05"/></geometry></collision>
        <inertial><mass value="0.1"/><inertia ixx="0.00014" ixy="0.0" ixz="0.0" iyy="0.00007" iyz="0.0" izz="0.00017"/></inertial>
    </link>
    <joint name="sensor_mount_joint" type="fixed"><parent link="base_link"/><child link="sensor_mount_link"/><origin xyz="0 0 0.139" rpy="0 0 0"/></joint>

    <link name="camera_link"/>
    <joint name="camera_joint" type="fixed"><parent link="sensor_mount_link"/><child link="camera_link"/><origin xyz="0 0 0" rpy="0 0 1.5708"/></joint>

    <gazebo reference="sensor_mount_link">
        <sensor type="gpu_lidar" name="lidar">
            <update_rate>10.0</update_rate>
            <topic>/scan</topic>
            <ignition_frame_id>sensor_mount_link</ignition_frame_id>
            <lidar>
                <scan>
                    <horizontal><samples>360</samples><resolution>1</resolution><min_angle>-3.14159</min_angle><max_angle>3.14159</max_angle></horizontal>
                </scan>
                <range><min>0.1</min><max>10.0</max><resolution>0.01</resolution></range>
            </lidar>
            <always_on>1</always_on>
            <visualize>true</visualize>
        </sensor>
    </gazebo>

    <gazebo reference="camera_link">
        <sensor type="rgbd_camera" name="rgbd_camera">
            <update_rate>15.0</update_rate>
            <topic>/camera</topic>
            <ignition_frame_id>camera_link</ignition_frame_id>
            <camera>
                <horizontal_fov>1.047198</horizontal_fov>
                <image><width>640</width><height>480</height></image>
                <clip><near>0.05</near><far>8.0</far></clip>
            </camera>
        </sensor>
    </gazebo>

    <gazebo>
        <plugin filename="ignition-gazebo-joint-state-publisher-system" name="ignition::gazebo::systems::JointStatePublisher">
            <topic>/joint_states</topic>
        </plugin>
    </gazebo>

    <gazebo>
        <plugin filename="ignition-gazebo-diff-drive-system" name="ignition::gazebo::systems::DiffDrive">
            <left_joint>wheel_left_joint</left_joint>
            <right_joint>wheel_right_joint</right_joint>
            <wheel_separation>0.386</wheel_separation>
            <wheel_radius>0.05</wheel_radius>
            <odom_publish_frequency>30</odom_publish_frequency>
            <topic>/cmd_vel</topic>
            <odom_topic>/odom</odom_topic>
            <frame_id>odom</frame_id>
            <child_frame_id>base_footprint</child_frame_id>
        </plugin>
    </gazebo>
</robot>